Workbook

Sheet COA TABLE FORM
A1: CATEGORY | B1: SUB CATEGORY | C1: COA Code - Account Name | D1: Code (helper) | E1: Category (trimmed helper)
A2: Entertainment Expenses | B2: Board & Committee Meeting Expenses | C2: 5006 - Entertainment Expenses | D2: =LEFT(C2,4) -> 5006 | E2: =TRIM(SUBSTITUTE(A2,CHAR(160)," ")) -> Entertainment Expenses
A3: Entertainment Expenses | B3: Entertainment | C3: 5006 - Entertainment Expenses | D3: =LEFT(C3,4) -> 5006 | E3: =TRIM(SUBSTITUTE(A3,CHAR(160)," ")) -> Entertainment Expenses
A4: Entertainment Expenses | B4: Guest Hospitality | C4: 5006 - Entertainment Expenses | D4: =LEFT(C4,4) -> 5006 | E4: =TRIM(SUBSTITUTE(A4,CHAR(160)," ")) -> Entertainment Expenses
A5: Charity/ Donation / General Expenses | B5: CSR Expenses | C5: 5001 - Charity/ Donation / General Expenses | D5: =LEFT(C5,4) -> 5001 | E5: =TRIM(SUBSTITUTE(A5,CHAR(160)," ")) -> Charity/ Donation / General Expenses
A6: Charity/ Donation / General Expenses | B6: Donations | C6: 5001 - Charity/ Donation / General Expenses | D6: =LEFT(C6,4) -> 5001 | E6: =TRIM(SUBSTITUTE(A6,CHAR(160)," ")) -> Charity/ Donation / General Expenses
A7: Fee Subscription & Membership | B7: Chamber & Association Membership | C7: 5004 - Fee Subscription & Membership | D7: =LEFT(C7,4) -> 5004 | E7: =TRIM(SUBSTITUTE(A7,CHAR(160)," ")) -> Fee Subscription & Membership
A8: Fee Subscription & Membership | B8: Cloud & Data Services | C8: 5004 - Fee Subscription & Membership | D8: =LEFT(C8,4) -> 5004 | E8: =TRIM(SUBSTITUTE(A8,CHAR(160)," ")) -> Fee Subscription & Membership
A9: Fee Subscription & Membership | B9: ERP Support & AMC | C9: 5004 - Fee Subscription & Membership | D9: =LEFT(C9,4) -> 5004 | E9: =TRIM(SUBSTITUTE(A9,CHAR(160)," ")) -> Fee Subscription & Membership
A10: Fee Subscription & Membership | B10: Newspapers, Books & Periodicals | C10: 5004 - Fee Subscription & Membership | D10: =LEFT(C10,4) -> 5004 | E10: =TRIM(SUBSTITUTE(A10,CHAR(160)," ")) -> Fee Subscription & Membership
A11: Fee Subscription & Membership | B11: SECP / Regulatory Filing Fees | C11: 5004 - Fee Subscription & Membership | D11: =LEFT(C11,4) -> 5004 | E11: =TRIM(SUBSTITUTE(A11,CHAR(160)," ")) -> Fee Subscription & Membership
A12: Fee Subscription & Membership | B12: Software Licences | C12: 5004 - Fee Subscription & Membership | D12: =LEFT(C12,4) -> 5004 | E12: =TRIM(SUBSTITUTE(A12,CHAR(160)," ")) -> Fee Subscription & Membership
A13: Fee Subscription & Membership | B13: Software Subscriptions - SaaS | C13: 5004 - Fee Subscription & Membership | D13: =LEFT(C13,4) -> 5004 | E13: =TRIM(SUBSTITUTE(A13,CHAR(160)," ")) -> Fee Subscription & Membership
... A66: Site Office Expenditure | B66: SITE EXPENSES | C66: 5007 - Site Office Expenditure | D66: =LEFT(C66,4) -> 5007 | E66: =TRIM(SUBSTITUTE(A66,CHAR(160)," ")) -> Site Office Expenditure

Sheet ITEM
A1: Category | B1: COA Code - Account Name | C1: Category | D1: Code | E1: Number in Item Name | F1: Item name | G1: Type | H1: Meter | I1: Location | J1: Account | K1: Amount | L1: COA | M1: Actions | N1: Sub Category | O1: Category Key (helper) | P1: Type Key
A2: =IFERROR(INDEX('COA TABLE FORM'!$A$2:$A$66,MATCH($O2,'COA TABLE FORM'!$E$2:$E$66,0)),"") -> Utilities Charges | B2: {=IFERROR(INDEX('COA TABLE FORM'!$C$2:$C$66,MATCH(1,('COA TABLE FORM'!$E$2:$E$66=$O2)*(ISNUMBER(SEARCH($P2,'COA TABLE FORM'!$B$2:$B$66))),0)),"")} -> 5012 - Water Charges | C2: CDA Water | D2: CSI-000108 | E2: =IFERROR(MID(F2,FIND("@",SUBSTITUTE(F2,"(","@",LEN(F2)-LEN(SUBSTITUTE(F2,"(",""))))+1,FIND("@",SUBSTITUTE(F2,")","@",LEN(F2)-LEN(SUBSTITUTE(F2,")",""))))-FIND("@",SUBSTITUTE(F2,"(","@",LEN(F2)-LEN(SUBSTITUTE(F2,"(",""))))-1),"") -> 6084000056 | F2: Muhammad Ilyas Khan Hafi,H#2 St#49 F-8/4 (6084000056) | G2: Water | H2: =E2 -> 6084000056 | I2: Muhammad Ilyas Khan Hafi,H#2 St#49 F-8/4 | J2: President Personal | K2: Rs 15,054 | L2: 6200 — Utilities Charges | N2: {=IFERROR(INDEX('COA TABLE FORM'!$B$2:$B$66,MATCH(1,('COA TABLE FORM'!$E$2:$E$66=$O2)*(ISNUMBER(SEARCH($P2,'COA TABLE FORM'!$B$2:$B$66))),0)),"")} -> Water | O2: =TRIM(MID($L2,FIND("—",$L2)+1,200)) -> Utilities Charges | P2: =IF($G2="Phone","Internet / Broadband",$G2) -> Water
A3: =IFERROR(INDEX('COA TABLE FORM'!$A$2:$A$66,MATCH($O3,'COA TABLE FORM'!$E$2:$E$66,0)),"") -> Utilities Charges | B3: {=IFERROR(INDEX('COA TABLE FORM'!$C$2:$C$66,MATCH(1,('COA TABLE FORM'!$E$2:$E$66=$O3)*(ISNUMBER(SEARCH($P3,'COA TABLE FORM'!$B$2:$B$66))),0)),"")} -> 5012 - Water Charges | C3: CDA Water | D3: CSI-000109 | E3: =IFERROR(MID(F3,FIND("@",SUBSTITUTE(F3,"(","@",LEN(F3)-LEN(SUBSTITUTE(F3,"(",""))))+1,FIND("@",SUBSTITUTE(F3,")","@",LEN(F3)-LEN(SUBSTITUTE(F3,")",""))))-FIND("@",SUBSTITUTE(F3,"(","@",LEN(F3)-LEN(SUBSTITUTE(F3,"(",""))))-1),"") -> 6084000058 | F3: Tanvver Ilyas,H#4,St# 49 F-8/4 Anexy Office (6084000058) | G3: Water | H3: =E3 -> 6084000058 | I3: Tanvver Ilyas,H#4,St# 49 F-8/4 Anexy Office | J3: President Personal | K3: Rs 15,054 | L3: 6200 — Utilities Charges | N3: {=IFERROR(INDEX('COA TABLE FORM'!$B$2:$B$66,MATCH(1,('COA TABLE FORM'!$E$2:$E$66=$O3)*(ISNUMBER(SEARCH($P3,'COA TABLE FORM'!$B$2:$B$66))),0)),"")} -> Water | O3: =TRIM(MID($L3,FIND("—",$L3)+1,200)) -> Utilities Charges | P3: =IF($G3="Phone","Internet / Broadband",$G3) -> Water
A4: =IFERROR(INDEX('COA TABLE FORM'!$A$2:$A$66,MATCH($O4,'COA TABLE FORM'!$E$2:$E$66,0)),"") -> Utilities Charges | B4: {=IFERROR(INDEX('COA TABLE FORM'!$C$2:$C$66,MATCH(1,('COA TABLE FORM'!$E$2:$E$66=$O4)*(ISNUMBER(SEARCH($P4,'COA TABLE FORM'!$B$2:$B$66))),0)),"")} -> 5012 - Water Charges | C4: CDA Water | D4: CSI-000110 | E4: =IFERROR(MID(F4,FIND("@",SUBSTITUTE(F4,"(","@",LEN(F4)-LEN(SUBSTITUTE(F4,"(",""))))+1,FIND("@",SUBSTITUTE(F4,")","@",LEN(F4)-LEN(SUBSTITUTE(F4,")",""))))-FIND("@",SUBSTITUTE(F4,"(","@",LEN(F4)-LEN(SUBSTITUTE(F4,"(",""))))-1),"") -> 6081000285 | F4: Samina AnnieTariq,H#12,St#37,F-8/1 (6081000285) | G4: Water | H4: =E4 -> 6081000285 | I4: Samina AnnieTariq,H#12,St#37,F-8/1 | J4: President Personal | K4: Rs 10,509 | L4: 6200 — Utilities Charges | N4: {=IFERROR(INDEX('COA TABLE FORM'!$B$2:$B$66,MATCH(1,('COA TABLE FORM'!$E$2:$E$66=$O4)*(ISNUMBER(SEARCH($P4,'COA TABLE FORM'!$B$2:$B$66))),0)),"")} -> Water | O4: =TRIM(MID($L4,FIND("—",$L4)+1,200)) -> Utilities Charges | P4: =IF($G4="Phone","Internet / Broadband",$G4) -> Water
A5: =IFERROR(INDEX('COA TABLE FORM'!$A$2:$A$66,MATCH($O5,'COA TABLE FORM'!$E$2:$E$66,0)),"") -> Utilities Charges | B5: {=IFERROR(INDEX('COA TABLE FORM'!$C$2:$C$66,MATCH(1,('COA TABLE FORM'!$E$2:$E$66=$O5)*(ISNUMBER(SEARCH($P5,'COA TABLE FORM'!$B$2:$B$66))),0)),"")} -> 5012 - Water Charges | C5: CDA Water | D5: CSI-000111 | E5: =IFERROR(MID(F5,FIND("@",SUBSTITUTE(F5,"(","@",LEN(F5)-LEN(SUBSTITUTE(F5,"(",""))))+1,FIND("@",SUBSTITUTE(F5,")","@",LEN(F5)-LEN(SUBSTITUTE(F5,")",""))))-FIND("@",SUBSTITUTE(F5,"(","@",LEN(F5)-LEN(SUBSTITUTE(F5,"(",""))))-1),"") -> 6081000276 | F5: Tanveer Ilys & Others,H#4-B St# 37 F-8/1 (6081000276) | G5: Water | H5: =E5 -> 6081000276 | I5: Tanveer Ilys & Others,H#4-B St# 37 F-8/1 | J5: President Personal | K5: Rs 8,145 | L5: 6200 — Utilities Charges | N5: {=IFERROR(INDEX('COA TABLE FORM'!$B$2:$B$66,MATCH(1,('COA TABLE FORM'!$E$2:$E$66=$O5)*(ISNUMBER(SEARCH($P5,'COA TABLE FORM'!$B$2:$B$66))),0)),"")} -> Water | O5: =TRIM(MID($L5,FIND("—",$L5)+1,200)) -> Utilities Charges | P5: =IF($G5="Phone","Internet / Broadband",$G5) -> Water
A6: =IFERROR(INDEX('COA TABLE FORM'!$A$2:$A$66,MATCH($O6,'COA TABLE FORM'!$E$2:$E$66,0)),"") -> Utilities Charges | B6: {=IFERROR(INDEX('COA TABLE FORM'!$C$2:$C$66,MATCH(1,('COA TABLE FORM'!$E$2:$E$66=$O6)*(ISNUMBER(SEARCH($P6,'COA TABLE FORM'!$B$2:$B$66))),0)),"")} -> 5012 - Water Charges | C6: CDA Water | D6: CSI-000112 | E6: =IFERROR(MID(F6,FIND("@",SUBSTITUTE(F6,"(","@",LEN(F6)-LEN(SUBSTITUTE(F6,"(",""))))+1,FIND("@",SUBSTITUTE(F6,")","@",LEN(F6)-LEN(SUBSTITUTE(F6,")",""))))-FIND("@",SUBSTITUTE(F6,"(","@",LEN(F6)-LEN(SUBSTITUTE(F6,"(",""))))-1),"") -> 6081000265 | F6: Maj.General M.R.Khan House # 5,St # 34 F-8/1 (6081000265) | G6: Water | H6: =E6 -> 6081000265 | I6: Maj.General M.R.Khan House # 5,St # 34 F-8/1 | J6: President Personal | K6: Rs 13,938 | L6: 6200 — Utilities Charges | N6: {=IFERROR(INDEX('COA TABLE FORM'!$B$2:$B$66,MATCH(1,('COA TABLE FORM'!$E$2:$E$66=$O6)*(ISNUMBER(SEARCH($P6,'COA TABLE FORM'!$B$2:$B$66))),0)),"")} -> Water | O6: =TRIM(MID($L6,FIND("—",$L6)+1,200)) -> Utilities Charges | P6: =IF($G6="Phone","Internet / Broadband",$G6) -> Water
A7: =IFERROR(INDEX('COA TABLE FORM'!$A$2:$A$66,MATCH($O7,'COA TABLE FORM'!$E$2:$E$66,0)),"") -> Utilities Charges | B7: {=IFERROR(INDEX('COA TABLE FORM'!$C$2:$C$66,MATCH(1,('COA TABLE FORM'!$E$2:$E$66=$O7)*(ISNUMBER(SEARCH($P7,'COA TABLE FORM'!$B$2:$B$66))),0)),"")} -> 5012 - Water Charges | C7: CDA Water | D7: CSI-000113 | E7: =IFERROR(MID(F7,FIND("@",SUBSTITUTE(F7,"(","@",LEN(F7)-LEN(SUBSTITUTE(F7,"(",""))))+1,FIND("@",SUBSTITUTE(F7,")","@",LEN(F7)-LEN(SUBSTITUTE(F7,")",""))))-FIND("@",SUBSTITUTE(F7,"(","@",LEN(F7)-LEN(SUBSTITUTE(F7,"(",""))))-1),"") -> 6081000389 | F7: Asma Tanveer,H#5,St#43, F-8/4, (6081000389) | G7: Water | H7: =E7 -> 6081000389 | I7: Asma Tanveer,H#5,St#43, F-8/4, | J7: President Personal | K7: Rs 12,994 | L7: 6200 — Utilities Charges | N7: {=IFERROR(INDEX('COA TABLE FORM'!$B$2:$B$66,MATCH(1,('COA TABLE FORM'!$E$2:$E$66=$O7)*(ISNUMBER(SEARCH($P7,'COA TABLE FORM'!$B$2:$B$66))),0)),"")} -> Water | O7: =TRIM(MID($L7,FIND("—",$L7)+1,200)) -> Utilities Charges | P7: =IF($G7="Phone","Internet / Broadband",$G7) -> Water
A8: =IFERROR(INDEX('COA TABLE FORM'!$A$2:$A$66,MATCH($O8,'COA TABLE FORM'!$E$2:$E$66,0)),"") -> Utilities Charges | B8: {=IFERROR(INDEX('COA TABLE FORM'!$C$2:$C$66,MATCH(1,('COA TABLE FORM'!$E$2:$E$66=$O8)*(ISNUMBER(SEARCH($P8,'COA TABLE FORM'!$B$2:$B$66))),0)),"")} -> 5012 - Water Charges | C8: CDA Water | D8: CSI-000114 | E8: =IFERROR(MID(F8,FIND("@",SUBSTITUTE(F8,"(","@",LEN(F8)-LEN(SUBSTITUTE(F8,"(",""))))+1,FIND("@",SUBSTITUTE(F8,")","@",LEN(F8)-LEN(SUBSTITUTE(F8,")",""))))-FIND("@",SUBSTITUTE(F8,"(","@",LEN(F8)-LEN(SUBSTITUTE(F8,"(",""))))-1),"") -> 6082000217 | F8: BegumNaseemHajazi & Others,H#40,Park Road F-8/2 (6082000217) | G8: Water | H8: =E8 -> 6082000217 | I8: BegumNaseemHajazi & Others,H#40,Park Road F-8/2 | J8: President Personal | K8: Rs 13,938 | L8: 6200 — Utilities Charges | N8: {=IFERROR(INDEX('COA TABLE FORM'!$B$2:$B$66,MATCH(1,('COA TABLE FORM'!$E$2:$E$66=$O8)*(ISNUMBER(SEARCH($P8,'COA TABLE FORM'!$B$2:$B$66))),0)),"")} -> Water | O8: =TRIM(MID($L8,FIND("—",$L8)+1,200)) -> Utilities Charges | P8: =IF($G8="Phone","Internet / Broadband",$G8) -> Water
A9: =IFERROR(INDEX('COA TABLE FORM'!$A$2:$A$66,MATCH($O9,'COA TABLE FORM'!$E$2:$E$66,0)),"") -> Utilities Charges | B9: {=IFERROR(INDEX('COA TABLE FORM'!$C$2:$C$66,MATCH(1,('COA TABLE FORM'!$E$2:$E$66=$O9)*(ISNUMBER(SEARCH($P9,'COA TABLE FORM'!$B$2:$B$66))),0)),"")} -> 5012 - Water Charges | C9: CDA Water | D9: CSI-000115 | E9: =IFERROR(MID(F9,FIND("@",SUBSTITUTE(F9,"(","@",LEN(F9)-LEN(SUBSTITUTE(F9,"(",""))))+1,FIND("@",SUBSTITUTE(F9,")","@",LEN(F9)-LEN(SUBSTITUTE(F9,")",""))))-FIND("@",SUBSTITUTE(F9,"(","@",LEN(F9)-LEN(SUBSTITUTE(F9,"(",""))))-1),"") -> 2838000216 | F9: Sardar Tanveer Ilyas Khan,App#1902,Tower A,Centaurus F-8/G-8 (2838000216) | G9: Water | H9: =E9 -> 2838000216 | I9: Sardar Tanveer Ilyas Khan,App#1902,Tower A,Centaurus F-8/G-8 | J9: President Personal | K9: Rs 6,924 | L9: 6200 — Utilities Charges | N9: {=IFERROR(INDEX('COA TABLE FORM'!$B$2:$B$66,MATCH(1,('COA TABLE FORM'!$E$2:$E$66=$O9)*(ISNUMBER(SEARCH($P9,'COA TABLE FORM'!$B$2:$B$66))),0)),"")} -> Water | O9: =TRIM(MID($L9,FIND("—",$L9)+1,200)) -> Utilities Charges | P9: =IF($G9="Phone","Internet / Broadband",$G9) -> Water
A10: =IFERROR(INDEX('COA TABLE FORM'!$A$2:$A$66,MATCH($O10,'COA TABLE FORM'!$E$2:$E$66,0)),"") -> Utilities Charges | B10: {=IFERROR(INDEX('COA TABLE FORM'!$C$2:$C$66,MATCH(1,('COA TABLE FORM'!$E$2:$E$66=$O10)*(ISNUMBER(SEARCH($P10,'COA TABLE FORM'!$B$2:$B$66))),0)),"")} -> 5012 - Water Charges | C10: CDA Water | D10: CSI-000116 | E10: =IFERROR(MID(F10,FIND("@",SUBSTITUTE(F10,"(","@",LEN(F10)-LEN(SUBSTITUTE(F10,"(",""))))+1,FIND("@",SUBSTITUTE(F10,")","@",LEN(F10)-LEN(SUBSTITUTE(F10,")",""))))-FIND("@",SUBSTITUTE(F10,"(","@",LEN(F10)-LEN(SUBSTITUTE(F10,"(",""))))-1),"") -> 2636000037 | F10: Mr.Tanveer Ilyas,21-W,Blue Area,F-6/G-6,Islamabad (2636000037) | G10: Water | H10: =E10 -> 2636000037 | I10: Mr.Tanveer Ilyas,21-W,Blue Area,F-6/G-6,Islamabad | J10: Head Office | K10: Rs 356,952 | L10: 6200 — Utilities Charges | N10: {=IFERROR(INDEX('COA TABLE FORM'!$B$2:$B$66,MATCH(1,('COA TABLE FORM'!$E$2:$E$66=$O10)*(ISNUMBER(SEARCH($P10,'COA TABLE FORM'!$B$2:$B$66))),0)),"")} -> Water | O10: =TRIM(MID($L10,FIND("—",$L10)+1,200)) -> Utilities Charges | P10: =IF($G10="Phone","Internet / Broadband",$G10) -> Water
A11: =IFERROR(INDEX('COA TABLE FORM'!$A$2:$A$66,MATCH($O11,'COA TABLE FORM'!$E$2:$E$66,0)),"") -> Utilities Charges | B11: {=IFERROR(INDEX('COA TABLE FORM'!$C$2:$C$66,MATCH(1,('COA TABLE FORM'!$E$2:$E$66=$O11)*(ISNUMBER(SEARCH($P11,'COA TABLE FORM'!$B$2:$B$66))),0)),"")} -> 5012 - Water Charges | C11: CDA Water | D11: CSI-000117 | E11: =IFERROR(MID(F11,FIND("@",SUBSTITUTE(F11,"(","@",LEN(F11)-LEN(SUBSTITUTE(F11,"(",""))))+1,FIND("@",SUBSTITUTE(F11,")","@",LEN(F11)-LEN(SUBSTITUTE(F11,")",""))))-FIND("@",SUBSTITUTE(F11,"(","@",LEN(F11)-LEN(SUBSTITUTE(F11,"(",""))))-1),"") -> 2838000439 | F11: Sardar Tanveer Ilyas,Appt#1708,Tower B,Centaurus F-8/G-8,Islamabad (2838000439) | G11: Water | H11: =E11 -> 2838000439 | I11: Sardar Tanveer Ilyas,Appt#1708,Tower B,Centaurus F-8/G-8,Islamabad | J11: President Personal | K11: Rs 40,500 | L11: 6200 — Utilities Charges | N11: {=IFERROR(INDEX('COA TABLE FORM'!$B$2:$B$66,MATCH(1,('COA TABLE FORM'!$E$2:$E$66=$O11)*(ISNUMBER(SEARCH($P11,'COA TABLE FORM'!$B$2:$B$66))),0)),"")} -> Water | O11: =TRIM(MID($L11,FIND("—",$L11)+1,200)) -> Utilities Charges | P11: =IF($G11="Phone","Internet / Broadband",$G11) -> Water
A12: =IFERROR(INDEX('COA TABLE FORM'!$A$2:$A$66,MATCH($O12,'COA TABLE FORM'!$E$2:$E$66,0)),"") -> Utilities Charges | B12: {=IFERROR(INDEX('COA TABLE FORM'!$C$2:$C$66,MATCH(1,('COA TABLE FORM'!$E$2:$E$66=$O12)*(ISNUMBER(SEARCH($P12,'COA TABLE FORM'!$B$2:$B$66))),0)),"")} -> 5012 - Water Charges | C12: CDA Water | D12: CSI-000118 | E12: =IFERROR(MID(F12,FIND("@",SUBSTITUTE(F12,"(","@",LEN(F12)-LEN(SUBSTITUTE(F12,"(",""))))+1,FIND("@",SUBSTITUTE(F12,")","@",LEN(F12)-LEN(SUBSTITUTE(F12,")",""))))-FIND("@",SUBSTITUTE(F12,"(","@",LEN(F12)-LEN(SUBSTITUTE(F12,"(",""))))-1),"") -> 2838000401 | F12: Sardar Tanveer Ilyas,Appt#1107,Tower B,Centaurus F-8/G-8,Islamabad (2838000401) | G12: Water | H12: =E12 -> 2838000401 | I12: Sardar Tanveer Ilyas,Appt#1107,Tower B,Centaurus F-8/G-8,Islamabad | J12: President Personal | K12: Rs 20,945 | L12: 6200 — Utilities Charges | N12: {=IFERROR(INDEX('COA TABLE FORM'!$B$2:$B$66,MATCH(1,('COA TABLE FORM'!$E$2:$E$66=$O12)*(ISNUMBER(SEARCH($P12,'COA TABLE FORM'!$B$2:$B$66))),0)),"")} -> Water | O12: =TRIM(MID($L12,FIND("—",$L12)+1,200)) -> Utilities Charges | P12: =IF($G12="Phone","Internet / Broadband",$G12) -> Water
A13: =IFERROR(INDEX('COA TABLE FORM'!$A$2:$A$66,MATCH($O13,'COA TABLE FORM'!$E$2:$E$66,0)),"") -> Utilities Charges | B13: {=IFERROR(INDEX('COA TABLE FORM'!$C$2:$C$66,MATCH(1,('COA TABLE FORM'!$E$2:$E$66=$O13)*(ISNUMBER(SEARCH($P13,'COA TABLE FORM'!$B$2:$B$66))),0)),"")} -> 5008 - ELECTRICITY CHARGES | C13: IESCO | D13: CSI-000001 | E13: =IFERROR(MID(F13,FIND("@",SUBSTITUTE(F13,"(","@",LEN(F13)-LEN(SUBSTITUTE(F13,"(",""))))+1,FIND("@",SUBSTITUTE(F13,")","@",LEN(F13)-LEN(SUBSTITUTE(F13,")",""))))-FIND("@",SUBSTITUTE(F13,"(","@",LEN(F13)-LEN(SUBSTITUTE(F13,"(",""))))-1),"") -> 3-P 60709 | F13: Shah Allah ditta (3-P 60709) | G13: Electricity | H13: 3-P 60709 | I13: Shah Allah ditta | J13: President Personal | K13: Rs 4,854 | L13: 6200 — Utilities Charges | N13: {=IFERROR(INDEX('COA TABLE FORM'!$B$2:$B$66,MATCH(1,('COA TABLE FORM'!$E$2:$E$66=$O13)*(ISNUMBER(SEARCH($P13,'COA TABLE FORM'!$B$2:$B$66))),0)),"")} -> Electricity | O13: =TRIM(MID($L13,FIND("—",$L13)+1,200)) -> Utilities Charges | P13: =IF($G13="Phone","Internet / Broadband",$G13) -> Electricity
A14: =IFERROR(INDEX('COA TABLE FORM'!$A$2:$A$66,MATCH($O14,'COA TABLE FORM'!$E$2:$E$66,0)),"") -> Utilities Charges | B14: {=IFERROR(INDEX('COA TABLE FORM'!$C$2:$C$66,MATCH(1,('COA TABLE FORM'!$E$2:$E$66=$O14)*(ISNUMBER(SEARCH($P14,'COA TABLE FORM'!$B$2:$B$66))),0)),"")} -> 5008 - ELECTRICITY CHARGES | C14: IESCO | D14: CSI-000002 | E14: =IFERROR(MID(F14,FIND("@",SUBSTITUTE(F14,"(","@",LEN(F14)-LEN(SUBSTITUTE(F14,"(",""))))+1,FIND("@",SUBSTITUTE(F14,")","@",LEN(F14)-LEN(SUBSTITUTE(F14,")",""))))-FIND("@",SUBSTITUTE(F14,"(","@",LEN(F14)-LEN(SUBSTITUTE(F14,"(",""))))-1),"") -> 3-P 35981 | F14: Farm House - H9 (3-P 35981) | G14: Electricity | H14: 3-P 35981 | I14: Farm House - H9 | J14: — | K14: Rs 174,927 | L14: 6200 — Utilities Charges | N14: {=IFERROR(INDEX('COA TABLE FORM'!$B$2:$B$66,MATCH(1,('COA TABLE FORM'!$E$2:$E$66=$O14)*(ISNUMBER(SEARCH($P14,'COA TABLE FORM'!$B$2:$B$66))),0)),"")} -> Electricity | O14: =TRIM(MID($L14,FIND("—",$L14)+1,200)) -> Utilities Charges | P14: =IF($G14="Phone","Internet / Broadband",$G14) -> Electricity
A15: =IFERROR(INDEX('COA TABLE FORM'!$A$2:$A$66,MATCH($O15,'COA TABLE FORM'!$E$2:$E$66,0)),"") -> Utilities Charges | B15: {=IFERROR(INDEX('COA TABLE FORM'!$C$2:$C$66,MATCH(1,('COA TABLE FORM'!$E$2:$E$66=$O15)*(ISNUMBER(SEARCH($P15,'COA TABLE FORM'!$B$2:$B$66))),0)),"")} -> 5008 - ELECTRICITY CHARGES | C15: IESCO | D15: CSI-000004 | E15: =IFERROR(MID(F15,FIND("@",SUBSTITUTE(F15,"(","@",LEN(F15)-LEN(SUBSTITUTE(F15,"(",""))))+1,FIND("@",SUBSTITUTE(F15,")","@",LEN(F15)-LEN(SUBSTITUTE(F15,")",""))))-FIND("@",SUBSTITUTE(F15,"(","@",LEN(F15)-LEN(SUBSTITUTE(F15,"(",""))))-1),"") -> 3-P 517209 | F15: Tanveer Ilyas Khan S/O M.Ilyas Khan PLOT#11, Orchard Scheeme,Murre Road,IBD (3-P 517209) | G15: Electricity | H15: 3-P 517209 | I15: Tanveer Ilyas Khan S/O M.Ilyas Khan PLOT#11, Orchard Scheeme,Murre Road,IBD | J15: President Personal | K15: Rs 7,501 | L15: 6200 — Utilities Charges | N15: {=IFERROR(INDEX('COA TABLE FORM'!$B$2:$B$66,MATCH(1,('COA TABLE FORM'!$E$2:$E$66=$O15)*(ISNUMBER(SEARCH($P15,'COA TABLE FORM'!$B$2:$B$66))),0)),"")} -> Electricity | O15: =TRIM(MID($L15,FIND("—",$L15)+1,200)) -> Utilities Charges | P15: =IF($G15="Phone","Internet / Broadband",$G15) -> Electricity
A16: =IFERROR(INDEX('COA TABLE FORM'!$A$2:$A$66,MATCH($O16,'COA TABLE FORM'!$E$2:$E$66,0)),"") -> Utilities Charges | B16: {=IFERROR(INDEX('COA TABLE FORM'!$C$2:$C$66,MATCH(1,('COA TABLE FORM'!$E$2:$E$66=$O16)*(ISNUMBER(SEARCH($P16,'COA TABLE FORM'!$B$2:$B$66))),0)),"")} -> 5008 - ELECTRICITY CHARGES | C16: IESCO | D16: CSI-000005 | E16: =IFERROR(MID(F16,FIND("@",SUBSTITUTE(F16,"(","@",LEN(F16)-LEN(SUBSTITUTE(F16,"(",""))))+1,FIND("@",SUBSTITUTE(F16,")","@",LEN(F16)-LEN(SUBSTITUTE(F16,")",""))))-FIND("@",SUBSTITUTE(F16,"(","@",LEN(F16)-LEN(SUBSTITUTE(F16,"(",""))))-1),"") -> 3-P 120063769 | F16: Sardar Tanveer Ilys Khan,H#4,St#49, F-8/4 Anexy Office (3-P 120063769) | G16: Electricity | H16: 3-P 120063769 | I16: Sardar Tanveer Ilys Khan,H#4,St#49, F-8/4 Anexy Office | J16: President Personal | K16: Rs 117,734 | L16: 6200 — Utilities Charges | N16: {=IFERROR(INDEX('COA TABLE FORM'!$B$2:$B$66,MATCH(1,('COA TABLE FORM'!$E$2:$E$66=$O16)*(ISNUMBER(SEARCH($P16,'COA TABLE FORM'!$B$2:$B$66))),0)),"")} -> Electricity | O16: =TRIM(MID($L16,FIND("—",$L16)+1,200)) -> Utilities Charges | P16: =IF($G16="Phone","Internet / Broadband",$G16) -> Electricity
A17: =IFERROR(INDEX('COA TABLE FORM'!$A$2:$A$66,MATCH($O17,'COA TABLE FORM'!$E$2:$E$66,0)),"") -> Utilities Charges | B17: {=IFERROR(INDEX('COA TABLE FORM'!$C$2:$C$66,MATCH(1,('COA TABLE FORM'!$E$2:$E$66=$O17)*(ISNUMBER(SEARCH($P17,'COA TABLE FORM'!$B$2:$B$66))),0)),"")} -> 5008 - ELECTRICITY CHARGES | C17: IESCO | D17: CSI-000006 | E17: =IFERROR(MID(F17,FIND("@",SUBSTITUTE(F17,"(","@",LEN(F17)-LEN(SUBSTITUTE(F17,"(",""))))+1,FIND("@",SUBSTITUTE(F17,")","@",LEN(F17)-LEN(SUBSTITUTE(F17,")",""))))-FIND("@",SUBSTITUTE(F17,"(","@",LEN(F17)-LEN(SUBSTITUTE(F17,"(",""))))-1),"") -> S-P 5378590 | F17: Sardar Tanveer Ilys Khan,H#4,St#49, F-8/4 Anexy Office (S-P 5378590) | G17: Electricity | H17: S-P 5378590 | I17: Sardar Tanveer Ilys Khan,H#4,St#49, F-8/4 Anexy Office | J17: President Personal | K17: Rs 124 | L17: 6200 — Utilities Charges | N17: {=IFERROR(INDEX('COA TABLE FORM'!$B$2:$B$66,MATCH(1,('COA TABLE FORM'!$E$2:$E$66=$O17)*(ISNUMBER(SEARCH($P17,'COA TABLE FORM'!$B$2:$B$66))),0)),"")} -> Electricity | O17: =TRIM(MID($L17,FIND("—",$L17)+1,200)) -> Utilities Charges | P17: =IF($G17="Phone","Internet / Broadband",$G17) -> Electricity
A18: =IFERROR(INDEX('COA TABLE FORM'!$A$2:$A$66,MATCH($O18,'COA TABLE FORM'!$E$2:$E$66,0)),"") -> Utilities Charges | B18: {=IFERROR(INDEX('COA TABLE FORM'!$C$2:$C$66,MATCH(1,('COA TABLE FORM'!$E$2:$E$66=$O18)*(ISNUMBER(SEARCH($P18,'COA TABLE FORM'!$B$2:$B$66))),0)),"")} -> 5008 - ELECTRICITY CHARGES | C18: IESCO | D18: CSI-000007 | E18: =IFERROR(MID(F18,FIND("@",SUBSTITUTE(F18,"(","@",LEN(F18)-LEN(SUBSTITUTE(F18,"(",""))))+1,FIND("@",SUBSTITUTE(F18,")","@",LEN(F18)-LEN(SUBSTITUTE(F18,")",""))))-FIND("@",SUBSTITUTE(F18,"(","@",LEN(F18)-LEN(SUBSTITUTE(F18,"(",""))))-1),"") -> S-P 828171 | F18: H-34, St 55, G-9/4 FCSS (S-P 828171) | G18: Electricity | H18: S-P 828171 | I18: H-34, St 55, G-9/4 FCSS | J18: President Personal | K18: Rs 36,113 | L18: 6200 — Utilities Charges | N18: {=IFERROR(INDEX('COA TABLE FORM'!$B$2:$B$66,MATCH(1,('COA TABLE FORM'!$E$2:$E$66=$O18)*(ISNUMBER(SEARCH($P18,'COA TABLE FORM'!$B$2:$B$66))),0)),"")} -> Electricity | O18: =TRIM(MID($L18,FIND("—",$L18)+1,200)) -> Utilities Charges | P18: =IF($G18="Phone","Internet / Broadband",$G18) -> Electricity
A19: =IFERROR(INDEX('COA TABLE FORM'!$A$2:$A$66,MATCH($O19,'COA TABLE FORM'!$E$2:$E$66,0)),"") -> Utilities Charges | B19: {=IFERROR(INDEX('COA TABLE FORM'!$C$2:$C$66,MATCH(1,('COA TABLE FORM'!$E$2:$E$66=$O19)*(ISNUMBER(SEARCH($P19,'COA TABLE FORM'!$B$2:$B$66))),0)),"")} -> 5008 - ELECTRICITY CHARGES | C19: IESCO | D19: CSI-000008 | E19: =IFERROR(MID(F19,FIND("@",SUBSTITUTE(F19,"(","@",LEN(F19)-LEN(SUBSTITUTE(F19,"(",""))))+1,FIND("@",SUBSTITUTE(F19,")","@",LEN(F19)-LEN(SUBSTITUTE(F19,")",""))))-FIND("@",SUBSTITUTE(F19,"(","@",LEN(F19)-LEN(SUBSTITUTE(F19,"(",""))))-1),"") -> 3-P301953 | F19: H-34, St 55, G-9/4 FCSS (3-P301953) | G19: Electricity | H19: 3-P301953 | I19: H-34, St 55, G-9/4 FCSS | J19: President Personal | K19: Rs 15,642 | L19: 6200 — Utilities Charges | N19: {=IFERROR(INDEX('COA TABLE FORM'!$B$2:$B$66,MATCH(1,('COA TABLE FORM'!$E$2:$E$66=$O19)*(ISNUMBER(SEARCH($P19,'COA TABLE FORM'!$B$2:$B$66))),0)),"")} -> Electricity | O19: =TRIM(MID($L19,FIND("—",$L19)+1,200)) -> Utilities Charges | P19: =IF($G19="Phone","Internet / Broadband",$G19) -> Electricity
A20: =IFERROR(INDEX('COA TABLE FORM'!$A$2:$A$66,MATCH($O20,'COA TABLE FORM'!$E$2:$E$66,0)),"") -> Utilities Charges | B20: {=IFERROR(INDEX('COA TABLE FORM'!$C$2:$C$66,MATCH(1,('COA TABLE FORM'!$E$2:$E$66=$O20)*(ISNUMBER(SEARCH($P20,'COA TABLE FORM'!$B$2:$B$66))),0)),"")} -> 5008 - ELECTRICITY CHARGES | C20: IESCO | D20: CSI-000009 | E20: =IFERROR(MID(F20,FIND("@",SUBSTITUTE(F20,"(","@",LEN(F20)-LEN(SUBSTITUTE(F20,"(",""))))+1,FIND("@",SUBSTITUTE(F20,")","@",LEN(F20)-LEN(SUBSTITUTE(F20,")",""))))-FIND("@",SUBSTITUTE(F20,"(","@",LEN(F20)-LEN(SUBSTITUTE(F20,"(",""))))-1),"") -> 1422400011463 | F20: Sardar M.Ilyas Khan S/O Muhammad Sharif Khan, House # 2,St # 49,F-8/4 (1422400011463) | G20: Electricity | H20: 1422400011463 | I20: Sardar M.Ilyas Khan S/O Muhammad Sharif Khan, House # 2,St # 49,F-8/4 | J20: President Personal | K20: Rs 732,228 | L20: 6200 — Utilities Charges | N20: {=IFERROR(INDEX('COA TABLE FORM'!$B$2:$B$66,MATCH(1,('COA TABLE FORM'!$E$2:$E$66=$O20)*(ISNUMBER(SEARCH($P20,'COA TABLE FORM'!$B$2:$B$66))),0)),"")} -> Electricity | O20: =TRIM(MID($L20,FIND("—",$L20)+1,200)) -> Utilities Charges | P20: =IF($G20="Phone","Internet / Broadband",$G20) -> Electricity
A21: =IFERROR(INDEX('COA TABLE FORM'!$A$2:$A$66,MATCH($O21,'COA TABLE FORM'!$E$2:$E$66,0)),"") -> Utilities Charges | B21: {=IFERROR(INDEX('COA TABLE FORM'!$C$2:$C$66,MATCH(1,('COA TABLE FORM'!$E$2:$E$66=$O21)*(ISNUMBER(SEARCH($P21,'COA TABLE FORM'!$B$2:$B$66))),0)),"")} -> 5008 - ELECTRICITY CHARGES | C21: IESCO | D21: CSI-000010 | E21: =IFERROR(MID(F21,FIND("@",SUBSTITUTE(F21,"(","@",LEN(F21)-LEN(SUBSTITUTE(F21,"(",""))))+1,FIND("@",SUBSTITUTE(F21,")","@",LEN(F21)-LEN(SUBSTITUTE(F21,")",""))))-FIND("@",SUBSTITUTE(F21,"(","@",LEN(F21)-LEN(SUBSTITUTE(F21,"(",""))))-1),"") -> S-P3300253 | F21: Sardar Tanveer Ilyas S/O M.Ilyas Khan Plot#21Office#5 3rd Floor F-11 Markaz (S-P3300253) | G21: Electricity | H21: S-P3300253 | I21: Sardar Tanveer Ilyas S/O M.Ilyas Khan Plot#21Office#5 3rd Floor F-11 Markaz | J21: President Personal | K21: Rs 1,402 | L21: 6200 — Utilities Charges | N21: {=IFERROR(INDEX('COA TABLE FORM'!$B$2:$B$66,MATCH(1,('COA TABLE FORM'!$E$2:$E$66=$O21)*(ISNUMBER(SEARCH($P21,'COA TABLE FORM'!$B$2:$B$66))),0)),"")} -> Electricity | O21: =TRIM(MID($L21,FIND("—",$L21)+1,200)) -> Utilities Charges | P21: =IF($G21="Phone","Internet / Broadband",$G21) -> Electricity
A22: =IFERROR(INDEX('COA TABLE FORM'!$A$2:$A$66,MATCH($O22,'COA TABLE FORM'!$E$2:$E$66,0)),"") -> Utilities Charges | B22: {=IFERROR(INDEX('COA TABLE FORM'!$C$2:$C$66,MATCH(1,('COA TABLE FORM'!$E$2:$E$66=$O22)*(ISNUMBER(SEARCH($P22,'COA TABLE FORM'!$B$2:$B$66))),0)),"")} -> 5008 - ELECTRICITY CHARGES | C22: IESCO | D22: CSI-000011 | E22: =IFERROR(MID(F22,FIND("@",SUBSTITUTE(F22,"(","@",LEN(F22)-LEN(SUBSTITUTE(F22,"(",""))))+1,FIND("@",SUBSTITUTE(F22,")","@",LEN(F22)-LEN(SUBSTITUTE(F22,")",""))))-FIND("@",SUBSTITUTE(F22,"(","@",LEN(F22)-LEN(SUBSTITUTE(F22,"(",""))))-1),"") -> S-P 3300228 | F22: Sardar Tanveer Ilyas S/O M.Ilyas Khan Plot#21Office#13 3rd Floor F-11 Markaz(New) Rented (S-P 3300228) | G22: Electricity | H22: S-P 3300228 | I22: Sardar Tanveer Ilyas S/O M.Ilyas Khan Plot#21Office#13 3rd Floor F-11 Markaz(New) Rented | J22: President Personal | K22: Rs 6,759 | L22: 6200 — Utilities Charges | N22: {=IFERROR(INDEX('COA TABLE FORM'!$B$2:$B$66,MATCH(1,('COA TABLE FORM'!$E$2:$E$66=$O22)*(ISNUMBER(SEARCH($P22,'COA TABLE FORM'!$B$2:$B$66))),0)),"")} -> Electricity | O22: =TRIM(MID($L22,FIND("—",$L22)+1,200)) -> Utilities Charges | P22: =IF($G22="Phone","Internet / Broadband",$G22) -> Electricity
A23: =IFERROR(INDEX('COA TABLE FORM'!$A$2:$A$66,MATCH($O23,'COA TABLE FORM'!$E$2:$E$66,0)),"") -> Utilities Charges | B23: {=IFERROR(INDEX('COA TABLE FORM'!$C$2:$C$66,MATCH(1,('COA TABLE FORM'!$E$2:$E$66=$O23)*(ISNUMBER(SEARCH($P23,'COA TABLE FORM'!$B$2:$B$66))),0)),"")} -> 5008 - ELECTRICITY CHARGES | C23: IESCO | D23: CSI-000012 | E23: =IFERROR(MID(F23,FIND("@",SUBSTITUTE(F23,"(","@",LEN(F23)-LEN(SUBSTITUTE(F23,"(",""))))+1,FIND("@",SUBSTITUTE(F23,")","@",LEN(F23)-LEN(SUBSTITUTE(F23,")",""))))-FIND("@",SUBSTITUTE(F23,"(","@",LEN(F23)-LEN(SUBSTITUTE(F23,"(",""))))-1),"") -> S-P-373797 | F23: Sardar Tanveer Ilyas S/O M.Ilyas Khan Plot#21,Office # 11,2nd Floor,F-11 Markaz(Rented) (S-P-373797) | G23: Electricity | H23: S-P-373797 | I23: Sardar Tanveer Ilyas S/O M.Ilyas Khan Plot#21,Office # 11,2nd Floor,F-11 Markaz(Rented) | J23: President Personal | K23: Rs 602 | L23: 6200 — Utilities Charges | N23: {=IFERROR(INDEX('COA TABLE FORM'!$B$2:$B$66,MATCH(1,('COA TABLE FORM'!$E$2:$E$66=$O23)*(ISNUMBER(SEARCH($P23,'COA TABLE FORM'!$B$2:$B$66))),0)),"")} -> Electricity | O23: =TRIM(MID($L23,FIND("—",$L23)+1,200)) -> Utilities Charges | P23: =IF($G23="Phone","Internet / Broadband",$G23) -> Electricity
A24: =IFERROR(INDEX('COA TABLE FORM'!$A$2:$A$66,MATCH($O24,'COA TABLE FORM'!$E$2:$E$66,0)),"") -> Utilities Charges | B24: {=IFERROR(INDEX('COA TABLE FORM'!$C$2:$C$66,MATCH(1,('COA TABLE FORM'!$E$2:$E$66=$O24)*(ISNUMBER(SEARCH($P24,'COA TABLE FORM'!$B$2:$B$66))),0)),"")} -> 5008 - ELECTRICITY CHARGES | C24: IESCO | D24: CSI-000013 | E24: =IFERROR(MID(F24,FIND("@",SUBSTITUTE(F24,"(","@",LEN(F24)-LEN(SUBSTITUTE(F24,"(",""))))+1,FIND("@",SUBSTITUTE(F24,")","@",LEN(F24)-LEN(SUBSTITUTE(F24,")",""))))-FIND("@",SUBSTITUTE(F24,"(","@",LEN(F24)-LEN(SUBSTITUTE(F24,"(",""))))-1),"") -> 3-P-21025 | F24: Mrs.Sameena Annie Tariq W/O Javed Tariq House # 12, Street # 37,F8/1 (3-P-21025) | G24: Electricity | H24: 3-P-21025 | I24: Mrs.Sameena Annie Tariq W/O Javed Tariq House # 12, Street # 37,F8/1 | J24: President Personal | K24: Rs 64,912 | L24: 6200 — Utilities Charges | N24: {=IFERROR(INDEX('COA TABLE FORM'!$B$2:$B$66,MATCH(1,('COA TABLE FORM'!$E$2:$E$66=$O24)*(ISNUMBER(SEARCH($P24,'COA TABLE FORM'!$B$2:$B$66))),0)),"")} -> Electricity | O24: =TRIM(MID($L24,FIND("—",$L24)+1,200)) -> Utilities Charges | P24: =IF($G24="Phone","Internet / Broadband",$G24) -> Electricity
A25: =IFERROR(INDEX('COA TABLE FORM'!$A$2:$A$66,MATCH($O25,'COA TABLE FORM'!$E$2:$E$66,0)),"") -> Utilities Charges | B25: {=IFERROR(INDEX('COA TABLE FORM'!$C$2:$C$66,MATCH(1,('COA TABLE FORM'!$E$2:$E$66=$O25)*(ISNUMBER(SEARCH($P25,'COA TABLE FORM'!$B$2:$B$66))),0)),"")} -> 5008 - ELECTRICITY CHARGES | C25: IESCO | D25: CSI-000014 | E25: =IFERROR(MID(F25,FIND("@",SUBSTITUTE(F25,"(","@",LEN(F25)-LEN(SUBSTITUTE(F25,"(",""))))+1,FIND("@",SUBSTITUTE(F25,")","@",LEN(F25)-LEN(SUBSTITUTE(F25,")",""))))-FIND("@",SUBSTITUTE(F25,"(","@",LEN(F25)-LEN(SUBSTITUTE(F25,"(",""))))-1),"") -> 3-P 5470205 | F25: M.Umer Tanveer S/O Tanveer Ilyas Plot#3 Class-3 Shoping Centre G8/4-4 (3-P 5470205) | G25: Electricity | H25: 3-P 5470205 | I25: M.Umer Tanveer S/O Tanveer Ilyas Plot#3 Class-3 Shoping Centre G8/4-4 | J25: President Personal | K25: Rs 8,889 | L25: 6200 — Utilities Charges | N25: {=IFERROR(INDEX('COA TABLE FORM'!$B$2:$B$66,MATCH(1,('COA TABLE FORM'!$E$2:$E$66=$O25)*(ISNUMBER(SEARCH($P25,'COA TABLE FORM'!$B$2:$B$66))),0)),"")} -> Electricity | O25: =TRIM(MID($L25,FIND("—",$L25)+1,200)) -> Utilities Charges | P25: =IF($G25="Phone","Internet / Broadband",$G25) -> Electricity
A26: =IFERROR(INDEX('COA TABLE FORM'!$A$2:$A$66,MATCH($O26,'COA TABLE FORM'!$E$2:$E$66,0)),"") -> Utilities Charges | B26: {=IFERROR(INDEX('COA TABLE FORM'!$C$2:$C$66,MATCH(1,('COA TABLE FORM'!$E$2:$E$66=$O26)*(ISNUMBER(SEARCH($P26,'COA TABLE FORM'!$B$2:$B$66))),0)),"")} -> 5008 - ELECTRICITY CHARGES | C26: IESCO | D26: CSI-000015 | E26: =IFERROR(MID(F26,FIND("@",SUBSTITUTE(F26,"(","@",LEN(F26)-LEN(SUBSTITUTE(F26,"(",""))))+1,FIND("@",SUBSTITUTE(F26,")","@",LEN(F26)-LEN(SUBSTITUTE(F26,")",""))))-FIND("@",SUBSTITUTE(F26,"(","@",LEN(F26)-LEN(SUBSTITUTE(F26,"(",""))))-1),"") -> 3-P 60709 | F26: Sardar Tanveer Ilyas S/O SardarM.Ilyas Shah Allah Ditta Farm (3-P 60709) | G26: Electricity | H26: 3-P 60709 | I26: Sardar Tanveer Ilyas S/O SardarM.Ilyas Shah Allah Ditta Farm | J26: President Personal | K26: Rs 27,239 | L26: 6200 — Utilities Charges | N26: {=IFERROR(INDEX('COA TABLE FORM'!$B$2:$B$66,MATCH(1,('COA TABLE FORM'!$E$2:$E$66=$O26)*(ISNUMBER(SEARCH($P26,'COA TABLE FORM'!$B$2:$B$66))),0)),"")} -> Electricity | O26: =TRIM(MID($L26,FIND("—",$L26)+1,200)) -> Utilities Charges | P26: =IF($G26="Phone","Internet / Broadband",$G26) -> Electricity
A27: =IFERROR(INDEX('COA TABLE FORM'!$A$2:$A$66,MATCH($O27,'COA TABLE FORM'!$E$2:$E$66,0)),"") -> Utilities Charges | B27: {=IFERROR(INDEX('COA TABLE FORM'!$C$2:$C$66,MATCH(1,('COA TABLE FORM'!$E$2:$E$66=$O27)*(ISNUMBER(SEARCH($P27,'COA TABLE FORM'!$B$2:$B$66))),0)),"")} -> 5008 - ELECTRICITY CHARGES | C27: IESCO | D27: CSI-000016 | E27: =IFERROR(MID(F27,FIND("@",SUBSTITUTE(F27,"(","@",LEN(F27)-LEN(SUBSTITUTE(F27,"(",""))))+1,FIND("@",SUBSTITUTE(F27,")","@",LEN(F27)-LEN(SUBSTITUTE(F27,")",""))))-FIND("@",SUBSTITUTE(F27,"(","@",LEN(F27)-LEN(SUBSTITUTE(F27,"(",""))))-1),"") -> SP-40008429 | F27: Tanveer IlyasS/O Muhammad Ilyas Khan H# B-21 Scheme#2 Chak Shahzad(President House) (SP-40008429) | G27: Electricity | H27: SP-40008429 | I27: Tanveer IlyasS/O Muhammad Ilyas Khan H# B-21 Scheme#2 Chak Shahzad(President House) | J27: President Personal | K27: Rs 522,290 | L27: 6200 — Utilities Charges | N27: {=IFERROR(INDEX('COA TABLE FORM'!$B$2:$B$66,MATCH(1,('COA TABLE FORM'!$E$2:$E$66=$O27)*(ISNUMBER(SEARCH($P27,'COA TABLE FORM'!$B$2:$B$66))),0)),"")} -> Electricity | O27: =TRIM(MID($L27,FIND("—",$L27)+1,200)) -> Utilities Charges | P27: =IF($G27="Phone","Internet / Broadband",$G27) -> Electricity
A28: =IFERROR(INDEX('COA TABLE FORM'!$A$2:$A$66,MATCH($O28,'COA TABLE FORM'!$E$2:$E$66,0)),"") -> Utilities Charges | B28: {=IFERROR(INDEX('COA TABLE FORM'!$C$2:$C$66,MATCH(1,('COA TABLE FORM'!$E$2:$E$66=$O28)*(ISNUMBER(SEARCH($P28,'COA TABLE FORM'!$B$2:$B$66))),0)),"")} -> 5008 - ELECTRICITY CHARGES | C28: IESCO | D28: CSI-000017 | E28: =IFERROR(MID(F28,FIND("@",SUBSTITUTE(F28,"(","@",LEN(F28)-LEN(SUBSTITUTE(F28,"(",""))))+1,FIND("@",SUBSTITUTE(F28,")","@",LEN(F28)-LEN(SUBSTITUTE(F28,")",""))))-FIND("@",SUBSTITUTE(F28,"(","@",LEN(F28)-LEN(SUBSTITUTE(F28,"(",""))))-1),"") -> 3-P 40008427 | F28: Tanveer IlyasS/O Muhammad Ilyas Khan H#1321/A Scheme-2 Chak Shahzad (3-P 40008427) | G28: Electricity | H28: 3-P 40008427 | I28: Tanveer IlyasS/O Muhammad Ilyas Khan H#1321/A Scheme-2 Chak Shahzad | J28: President Personal | K28: Rs 127,429 | L28: 6200 — Utilities Charges | N28: {=IFERROR(INDEX('COA TABLE FORM'!$B$2:$B$66,MATCH(1,('COA TABLE FORM'!$E$2:$E$66=$O28)*(ISNUMBER(SEARCH($P28,'COA TABLE FORM'!$B$2:$B$66))),0)),"")} -> Electricity | O28: =TRIM(MID($L28,FIND("—",$L28)+1,200)) -> Utilities Charges | P28: =IF($G28="Phone","Internet / Broadband",$G28) -> Electricity
A29: =IFERROR(INDEX('COA TABLE FORM'!$A$2:$A$66,MATCH($O29,'COA TABLE FORM'!$E$2:$E$66,0)),"") -> Utilities Charges | B29: {=IFERROR(INDEX('COA TABLE FORM'!$C$2:$C$66,MATCH(1,('COA TABLE FORM'!$E$2:$E$66=$O29)*(ISNUMBER(SEARCH($P29,'COA TABLE FORM'!$B$2:$B$66))),0)),"")} -> 5008 - ELECTRICITY CHARGES | C29: IESCO | D29: CSI-000019 | E29: =IFERROR(MID(F29,FIND("@",SUBSTITUTE(F29,"(","@",LEN(F29)-LEN(SUBSTITUTE(F29,"(",""))))+1,FIND("@",SUBSTITUTE(F29,")","@",LEN(F29)-LEN(SUBSTITUTE(F29,")",""))))-FIND("@",SUBSTITUTE(F29,"(","@",LEN(F29)-LEN(SUBSTITUTE(F29,"(",""))))-1),"") -> 3-P 40008426 | F29: Tanveer Ilyas S/O Muhammad Ilyas Khan H # B-21/A Scheme-2 Chak Shahzad (3-P 40008426) | G29: Electricity | H29: 3-P 40008426 | I29: Tanveer Ilyas S/O Muhammad Ilyas Khan H # B-21/A Scheme-2 Chak Shahzad | J29: President Personal | K29: Rs 109,757 | L29: 6200 — Utilities Charges | N29: {=IFERROR(INDEX('COA TABLE FORM'!$B$2:$B$66,MATCH(1,('COA TABLE FORM'!$E$2:$E$66=$O29)*(ISNUMBER(SEARCH($P29,'COA TABLE FORM'!$B$2:$B$66))),0)),"")} -> Electricity | O29: =TRIM(MID($L29,FIND("—",$L29)+1,200)) -> Utilities Charges | P29: =IF($G29="Phone","Internet / Broadband",$G29) -> Electricity
A30: =IFERROR(INDEX('COA TABLE FORM'!$A$2:$A$66,MATCH($O30,'COA TABLE FORM'!$E$2:$E$66,0)),"") -> Utilities Charges | B30: {=IFERROR(INDEX('COA TABLE FORM'!$C$2:$C$66,MATCH(1,('COA TABLE FORM'!$E$2:$E$66=$O30)*(ISNUMBER(SEARCH($P30,'COA TABLE FORM'!$B$2:$B$66))),0)),"")} -> 5008 - ELECTRICITY CHARGES | C30: IESCO | D30: CSI-000020 | E30: =IFERROR(MID(F30,FIND("@",SUBSTITUTE(F30,"(","@",LEN(F30)-LEN(SUBSTITUTE(F30,"(",""))))+1,FIND("@",SUBSTITUTE(F30,")","@",LEN(F30)-LEN(SUBSTITUTE(F30,")",""))))-FIND("@",SUBSTITUTE(F30,"(","@",LEN(F30)-LEN(SUBSTITUTE(F30,"(",""))))-1),"") -> S-P 9729378 | F30: Sardar Tanveer Ilyas S/O M.Ilyas KhanThanda Pani Plot (S-P 9729378) | G30: Electricity | H30: S-P 9729378 | I30: Sardar Tanveer Ilyas S/O M.Ilyas KhanThanda Pani Plot | J30: President Personal | K30: Rs 1,200 | L30: 6200 — Utilities Charges | N30: {=IFERROR(INDEX('COA TABLE FORM'!$B$2:$B$66,MATCH(1,('COA TABLE FORM'!$E$2:$E$66=$O30)*(ISNUMBER(SEARCH($P30,'COA TABLE FORM'!$B$2:$B$66))),0)),"")} -> Electricity | O30: =TRIM(MID($L30,FIND("—",$L30)+1,200)) -> Utilities Charges | P30: =IF($G30="Phone","Internet / Broadband",$G30) -> Electricity
A31: =IFERROR(INDEX('COA TABLE FORM'!$A$2:$A$66,MATCH($O31,'COA TABLE FORM'!$E$2:$E$66,0)),"") -> Utilities Charges | B31: {=IFERROR(INDEX('COA TABLE FORM'!$C$2:$C$66,MATCH(1,('COA TABLE FORM'!$E$2:$E$66=$O31)*(ISNUMBER(SEARCH($P31,'COA TABLE FORM'!$B$2:$B$66))),0)),"")} -> 5008 - ELECTRICITY CHARGES | C31: IESCO | D31: CSI-000021 | E31: =IFERROR(MID(F31,FIND("@",SUBSTITUTE(F31,"(","@",LEN(F31)-LEN(SUBSTITUTE(F31,"(",""))))+1,FIND("@",SUBSTITUTE(F31,")","@",LEN(F31)-LEN(SUBSTITUTE(F31,")",""))))-FIND("@",SUBSTITUTE(F31,"(","@",LEN(F31)-LEN(SUBSTITUTE(F31,"(",""))))-1),"") -> 3-P 01322400015801 | F31: Mushtaq Ahmad S/o Muhammad Din Vill Konjri Dakhli Mourat Thalian Fateh Jang (3-P 01322400015801) | G31: Electricity | H31: 3-P 01322400015801 | I31: Mushtaq Ahmad S/o Muhammad Din Vill Konjri Dakhli Mourat Thalian Fateh Jang | J31: President Personal | K31: Rs 32,907 | L31: 6200 — Utilities Charges | N31: {=IFERROR(INDEX('COA TABLE FORM'!$B$2:$B$66,MATCH(1,('COA TABLE FORM'!$E$2:$E$66=$O31)*(ISNUMBER(SEARCH($P31,'COA TABLE FORM'!$B$2:$B$66))),0)),"")} -> Electricity | O31: =TRIM(MID($L31,FIND("—",$L31)+1,200)) -> Utilities Charges | P31: =IF($G31="Phone","Internet / Broadband",$G31) -> Electricity
A32: =IFERROR(INDEX('COA TABLE FORM'!$A$2:$A$66,MATCH($O32,'COA TABLE FORM'!$E$2:$E$66,0)),"") -> Utilities Charges | B32: {=IFERROR(INDEX('COA TABLE FORM'!$C$2:$C$66,MATCH(1,('COA TABLE FORM'!$E$2:$E$66=$O32)*(ISNUMBER(SEARCH($P32,'COA TABLE FORM'!$B$2:$B$66))),0)),"")} -> 5008 - ELECTRICITY CHARGES | C32: IESCO | D32: CSI-000022 | E32: =IFERROR(MID(F32,FIND("@",SUBSTITUTE(F32,"(","@",LEN(F32)-LEN(SUBSTITUTE(F32,"(",""))))+1,FIND("@",SUBSTITUTE(F32,")","@",LEN(F32)-LEN(SUBSTITUTE(F32,")",""))))-FIND("@",SUBSTITUTE(F32,"(","@",LEN(F32)-LEN(SUBSTITUTE(F32,"(",""))))-1),"") -> A00004 | F32: Tanveer Ilyas, S/O Muhammad Ilyas Khan,Sardar Palace Bangion Rawalakot,AJK (A00004) | G32: Electricity | H32: A00004 | I32: Tanveer Ilyas, S/O Muhammad Ilyas Khan,Sardar Palace Bangion Rawalakot,AJK | J32: President Personal | K32: Rs 33,564 | L32: 6200 — Utilities Charges | N32: {=IFERROR(INDEX('COA TABLE FORM'!$B$2:$B$66,MATCH(1,('COA TABLE FORM'!$E$2:$E$66=$O32)*(ISNUMBER(SEARCH($P32,'COA TABLE FORM'!$B$2:$B$66))),0)),"")} -> Electricity | O32: =TRIM(MID($L32,FIND("—",$L32)+1,200)) -> Utilities Charges | P32: =IF($G32="Phone","Internet / Broadband",$G32) -> Electricity
... A36: =IFERROR(INDEX('COA TABLE FORM'!$A$2:$A$66,MATCH($O36,'COA TABLE FORM'!$E$2:$E$66,0)),"") -> Utilities Charges | B36: {=IFERROR(INDEX('COA TABLE FORM'!$C$2:$C$66,MATCH(1,('COA TABLE FORM'!$E$2:$E$66=$O36)*(ISNUMBER(SEARCH($P36,'COA TABLE FORM'!$B$2:$B$66))),0)),"")} -> 5008 - ELECTRICITY CHARGES | C36: IESCO | D36: CSI-000026 | E36: =IFERROR(MID(F36,FIND("@",SUBSTITUTE(F36,"(","@",LEN(F36)-LEN(SUBSTITUTE(F36,"(",""))))+1,FIND("@",SUBSTITUTE(F36,")","@",LEN(F36)-LEN(SUBSTITUTE(F36,")",""))))-FIND("@",SUBSTITUTE(F36,"(","@",LEN(F36)-LEN(SUBSTITUTE(F36,"(",""))))-1),"") -> 3-P422 | F36: Shaukat Ali S/O Ahmad Din /H-5, St 43, F-8/1 (3-P422) | G36: Electricity | H36: 3-P422 | I36: Shaukat Ali S/O Ahmad Din /H-5, St 43, F-8/1 | J36: SGC | K36: Rs 104,977 | L36: 6200 — Utilities Charges | N36: {=IFERROR(INDEX('COA TABLE FORM'!$B$2:$B$66,MATCH(1,('COA TABLE FORM'!$E$2:$E$66=$O36)*(ISNUMBER(SEARCH($P36,'COA TABLE FORM'!$B$2:$B$66))),0)),"")} -> Electricity | O36: =TRIM(MID($L36,FIND("—",$L36)+1,200)) -> Utilities Charges | P36: =IF($G36="Phone","Internet / Broadband",$G36) -> Electricity
A37: =IFERROR(INDEX('COA TABLE FORM'!$A$2:$A$66,MATCH($O37,'COA TABLE FORM'!$E$2:$E$66,0)),"") -> Utilities Charges | B37: {=IFERROR(INDEX('COA TABLE FORM'!$C$2:$C$66,MATCH(1,('COA TABLE FORM'!$E$2:$E$66=$O37)*(ISNUMBER(SEARCH($P37,'COA TABLE FORM'!$B$2:$B$66))),0)),"")} -> 5008 - ELECTRICITY CHARGES | C37: IESCO | D37: CSI-000033 | E37: =IFERROR(MID(F37,FIND("@",SUBSTITUTE(F37,"(","@",LEN(F37)-LEN(SUBSTITUTE(F37,"(",""))))+1,FIND("@",SUBSTITUTE(F37,")","@",LEN(F37)-LEN(SUBSTITUTE(F37,")",""))))-FIND("@",SUBSTITUTE(F37,"(","@",LEN(F37)-LEN(SUBSTITUTE(F37,"(",""))))-1),"") -> 1859 | F37: Mrs.Farida Afzal/Muhammad Afzal/House # 5,St # 34 F-8/1 (1859) | G37: Electricity | H37: 1859 | I37: Mrs.Farida Afzal/Muhammad Afzal/House # 5,St # 34 F-8/1 | J37: SGC | K37: Rs 104,117 | L37: 6200 — Utilities Charges | N37: {=IFERROR(INDEX('COA TABLE FORM'!$B$2:$B$66,MATCH(1,('COA TABLE FORM'!$E$2:$E$66=$O37)*(ISNUMBER(SEARCH($P37,'COA TABLE FORM'!$B$2:$B$66))),0)),"")} -> Electricity | O37: =TRIM(MID($L37,FIND("—",$L37)+1,200)) -> Utilities Charges | P37: =IF($G37="Phone","Internet / Broadband",$G37) -> Electricity
A38: =IFERROR(INDEX('COA TABLE FORM'!$A$2:$A$66,MATCH($O38,'COA TABLE FORM'!$E$2:$E$66,0)),"") -> Utilities Charges | B38: {=IFERROR(INDEX('COA TABLE FORM'!$C$2:$C$66,MATCH(1,('COA TABLE FORM'!$E$2:$E$66=$O38)*(ISNUMBER(SEARCH($P38,'COA TABLE FORM'!$B$2:$B$66))),0)),"")} -> 5008 - ELECTRICITY CHARGES | C38: IESCO | D38: CSI-000034 | E38: =IFERROR(MID(F38,FIND("@",SUBSTITUTE(F38,"(","@",LEN(F38)-LEN(SUBSTITUTE(F38,"(",""))))+1,FIND("@",SUBSTITUTE(F38,")","@",LEN(F38)-LEN(SUBSTITUTE(F38,")",""))))-FIND("@",SUBSTITUTE(F38,"(","@",LEN(F38)-LEN(SUBSTITUTE(F38,"(",""))))-1),"") -> 261267 | F38: M.A.R.Khan/House # 5,St # 34 F-8/1 (261267) | G38: Electricity | H38: 261267 | I38: M.A.R.Khan/House # 5,St # 34 F-8/1 | J38: SGC | K38: Rs 287,444 | L38: 6200 — Utilities Charges | N38: {=IFERROR(INDEX('COA TABLE FORM'!$B$2:$B$66,MATCH(1,('COA TABLE FORM'!$E$2:$E$66=$O38)*(ISNUMBER(SEARCH($P38,'COA TABLE FORM'!$B$2:$B$66))),0)),"")} -> Electricity | O38: =TRIM(MID($L38,FIND("—",$L38)+1,200)) -> Utilities Charges | P38: =IF($G38="Phone","Internet / Broadband",$G38) -> Electricity
A39: =IFERROR(INDEX('COA TABLE FORM'!$A$2:$A$66,MATCH($O39,'COA TABLE FORM'!$E$2:$E$66,0)),"") -> Utilities Charges | B39: {=IFERROR(INDEX('COA TABLE FORM'!$C$2:$C$66,MATCH(1,('COA TABLE FORM'!$E$2:$E$66=$O39)*(ISNUMBER(SEARCH($P39,'COA TABLE FORM'!$B$2:$B$66))),0)),"")} -> 5008 - ELECTRICITY CHARGES | C39: IESCO | D39: CSI-000035 | E39: =IFERROR(MID(F39,FIND("@",SUBSTITUTE(F39,"(","@",LEN(F39)-LEN(SUBSTITUTE(F39,"(",""))))+1,FIND("@",SUBSTITUTE(F39,")","@",LEN(F39)-LEN(SUBSTITUTE(F39,")",""))))-FIND("@",SUBSTITUTE(F39,"(","@",LEN(F39)-LEN(SUBSTITUTE(F39,"(",""))))-1),"") -> S-P1748952 | F39: Sardar Tanveer Ilyas Khan S/O Sardar M.Ilyas Khan/Shop#1,P-21,W.Ground Floor,Blue Area (S-P1748952) | G39: Electricity | H39: S-P1748952 | I39: Sardar Tanveer Ilyas Khan S/O Sardar M.Ilyas Khan/Shop#1,P-21,W.Ground Floor,Blue Area | J39: SGC | K39: Rs 7,712 | L39: 6200 — Utilities Charges | N39: {=IFERROR(INDEX('COA TABLE FORM'!$B$2:$B$66,MATCH(1,('COA TABLE FORM'!$E$2:$E$66=$O39)*(ISNUMBER(SEARCH($P39,'COA TABLE FORM'!$B$2:$B$66))),0)),"")} -> Electricity | O39: =TRIM(MID($L39,FIND("—",$L39)+1,200)) -> Utilities Charges | P39: =IF($G39="Phone","Internet / Broadband",$G39) -> Electricity
A40: =IFERROR(INDEX('COA TABLE FORM'!$A$2:$A$66,MATCH($O40,'COA TABLE FORM'!$E$2:$E$66,0)),"") -> Utilities Charges | B40: {=IFERROR(INDEX('COA TABLE FORM'!$C$2:$C$66,MATCH(1,('COA TABLE FORM'!$E$2:$E$66=$O40)*(ISNUMBER(SEARCH($P40,'COA TABLE FORM'!$B$2:$B$66))),0)),"")} -> 5008 - ELECTRICITY CHARGES | C40: IESCO | D40: CSI-000036 | E40: =IFERROR(MID(F40,FIND("@",SUBSTITUTE(F40,"(","@",LEN(F40)-LEN(SUBSTITUTE(F40,"(",""))))+1,FIND("@",SUBSTITUTE(F40,")","@",LEN(F40)-LEN(SUBSTITUTE(F40,")",""))))-FIND("@",SUBSTITUTE(F40,"(","@",LEN(F40)-LEN(SUBSTITUTE(F40,"(",""))))-1),"") -> 335053 | F40: Sardar Tanveer Ilyas Khan S/O M.Ilyas Khan/P-NO21WShop#1-A Bule Area (335053) | G40: Electricity | H40: 335053 | I40: Sardar Tanveer Ilyas Khan S/O M.Ilyas Khan/P-NO21WShop#1-A Bule Area | J40: SGC | K40: Rs 2,128 | L40: 6200 — Utilities Charges | N40: {=IFERROR(INDEX('COA TABLE FORM'!$B$2:$B$66,MATCH(1,('COA TABLE FORM'!$E$2:$E$66=$O40)*(ISNUMBER(SEARCH($P40,'COA TABLE FORM'!$B$2:$B$66))),0)),"")} -> Electricity | O40: =TRIM(MID($L40,FIND("—",$L40)+1,200)) -> Utilities Charges | P40: =IF($G40="Phone","Internet / Broadband",$G40) -> Electricity
A41: =IFERROR(INDEX('COA TABLE FORM'!$A$2:$A$66,MATCH($O41,'COA TABLE FORM'!$E$2:$E$66,0)),"") -> Utilities Charges | B41: {=IFERROR(INDEX('COA TABLE FORM'!$C$2:$C$66,MATCH(1,('COA TABLE FORM'!$E$2:$E$66=$O41)*(ISNUMBER(SEARCH($P41,'COA TABLE FORM'!$B$2:$B$66))),0)),"")} -> 5008 - ELECTRICITY CHARGES | C41: IESCO | D41: CSI-000037 | E41: =IFERROR(MID(F41,FIND("@",SUBSTITUTE(F41,"(","@",LEN(F41)-LEN(SUBSTITUTE(F41,"(",""))))+1,FIND("@",SUBSTITUTE(F41,")","@",LEN(F41)-LEN(SUBSTITUTE(F41,")",""))))-FIND("@",SUBSTITUTE(F41,"(","@",LEN(F41)-LEN(SUBSTITUTE(F41,"(",""))))-1),"") -> 1422400011607 | F41: Sardar Tanveer Ilyas Khan,Sardar Plaza Blue Area,P.No21-W,Fazal-E-Rd.Isb (1422400011607) | G41: Electricity | H41: 1422400011607 | I41: Sardar Tanveer Ilyas Khan,Sardar Plaza Blue Area,P.No21-W,Fazal-E-Rd.Isb | J41: SGC | K41: Rs 320,266 | L41: 6200 — Utilities Charges | N41: {=IFERROR(INDEX('COA TABLE FORM'!$B$2:$B$66,MATCH(1,('COA TABLE FORM'!$E$2:$E$66=$O41)*(ISNUMBER(SEARCH($P41,'COA TABLE FORM'!$B$2:$B$66))),0)),"")} -> Electricity | O41: =TRIM(MID($L41,FIND("—",$L41)+1,200)) -> Utilities Charges | P41: =IF($G41="Phone","Internet / Broadband",$G41) -> Electricity
A42: =IFERROR(INDEX('COA TABLE FORM'!$A$2:$A$66,MATCH($O42,'COA TABLE FORM'!$E$2:$E$66,0)),"") -> Utilities Charges | B42: {=IFERROR(INDEX('COA TABLE FORM'!$C$2:$C$66,MATCH(1,('COA TABLE FORM'!$E$2:$E$66=$O42)*(ISNUMBER(SEARCH($P42,'COA TABLE FORM'!$B$2:$B$66))),0)),"")} -> 5008 - ELECTRICITY CHARGES | C42: IESCO | D42: CSI-000038 | E42: =IFERROR(MID(F42,FIND("@",SUBSTITUTE(F42,"(","@",LEN(F42)-LEN(SUBSTITUTE(F42,"(",""))))+1,FIND("@",SUBSTITUTE(F42,")","@",LEN(F42)-LEN(SUBSTITUTE(F42,")",""))))-FIND("@",SUBSTITUTE(F42,"(","@",LEN(F42)-LEN(SUBSTITUTE(F42,"(",""))))-1),"") -> S-P 184614 | F42: Ch.Khizar Hayat/Ch.Muhammad Akram Dhoke Kazim Building (Tarlai) (S-P 184614) | G42: Electricity | H42: S-P 184614 | I42: Ch.Khizar Hayat/Ch.Muhammad Akram Dhoke Kazim Building (Tarlai) | J42: SGC | K42: Rs 149,606 | L42: 6200 — Utilities Charges | N42: {=IFERROR(INDEX('COA TABLE FORM'!$B$2:$B$66,MATCH(1,('COA TABLE FORM'!$E$2:$E$66=$O42)*(ISNUMBER(SEARCH($P42,'COA TABLE FORM'!$B$2:$B$66))),0)),"")} -> Electricity | O42: =TRIM(MID($L42,FIND("—",$L42)+1,200)) -> Utilities Charges | P42: =IF($G42="Phone","Internet / Broadband",$G42) -> Electricity
A43: =IFERROR(INDEX('COA TABLE FORM'!$A$2:$A$66,MATCH($O43,'COA TABLE FORM'!$E$2:$E$66,0)),"") -> Utilities Charges | B43: {=IFERROR(INDEX('COA TABLE FORM'!$C$2:$C$66,MATCH(1,('COA TABLE FORM'!$E$2:$E$66=$O43)*(ISNUMBER(SEARCH($P43,'COA TABLE FORM'!$B$2:$B$66))),0)),"")} -> 5008 - ELECTRICITY CHARGES | C43: IESCO | D43: CSI-000039 | E43: =IFERROR(MID(F43,FIND("@",SUBSTITUTE(F43,"(","@",LEN(F43)-LEN(SUBSTITUTE(F43,"(",""))))+1,FIND("@",SUBSTITUTE(F43,")","@",LEN(F43)-LEN(SUBSTITUTE(F43,")",""))))-FIND("@",SUBSTITUTE(F43,"(","@",LEN(F43)-LEN(SUBSTITUTE(F43,"(",""))))-1),"") -> S-P 358882 | F43: Muhammad Ilyas S/O Abdul Rehman Dhoke Kazim Building (Tarlai) (S-P 358882) | G43: Electricity | H43: S-P 358882 | I43: Muhammad Ilyas S/O Abdul Rehman Dhoke Kazim Building (Tarlai) | J43: SGC | K43: Rs 101,960 | L43: 6200 — Utilities Charges | N43: {=IFERROR(INDEX('COA TABLE FORM'!$B$2:$B$66,MATCH(1,('COA TABLE FORM'!$E$2:$E$66=$O43)*(ISNUMBER(SEARCH($P43,'COA TABLE FORM'!$B$2:$B$66))),0)),"")} -> Electricity | O43: =TRIM(MID($L43,FIND("—",$L43)+1,200)) -> Utilities Charges | P43: =IF($G43="Phone","Internet / Broadband",$G43) -> Electricity
...
